test test_calendar failed

test test_cfgparser failed -- multiple errors occurred; run in verbose mode for details

test test_codecs failed -- Traceback (most recent call last):
  File "/var/pisi/python-2.7.2-70/work/Python-2.7.2/Lib/test/test_codecs.py", line 805, in test_decode
    self.assertEqual(uni, puny.decode("punycode"))
  File "/var/pisi/python-2.7.2-70/work/Python-2.7.2/Lib/encodings/punycode.py", line 208, in decode
    res = punycode_decode(input, errors)
  File "/var/pisi/python-2.7.2-70/work/Python-2.7.2/Lib/encodings/punycode.py", line 195, in punycode_decode
    return insertion_sort(base, extended, errors)
  File "/var/pisi/python-2.7.2-70/work/Python-2.7.2/Lib/encodings/punycode.py", line 168, in insertion_sort
    bias, errors)
  File "/var/pisi/python-2.7.2-70/work/Python-2.7.2/Lib/encodings/punycode.py", line 149, in decode_generalized_number
    % extended[extpos])
UnicodeError: Invalid extended code point 'H'

test test_decimal failed -- multiple errors occurred; run in verbose mode for details

test_deque
**********************************************************************
File "/var/pisi/python-2.7.2-70/work/Python-2.7.2/Lib/test/test_deque.py", line ?, in test.test_deque.__test__.libreftest
Failed example:
    for elem in d:                   # iterate over the deque's elements
        print elem.upper()
Expected:
    G
    H
    I
Got:
    G
    H
    i
**********************************************************************
1 items had failures:
   1 of  32 in test.test_deque.__test__.libreftest
***Test Failed*** 1 failures.
test test_deque failed -- 1 of 32 doctests failed

test test_email failed -- multiple errors occurred; run in verbose mode for details

test test_email_renamed failed -- multiple errors occurred; run in verbose mode for details

test test_fileinput failed -- Traceback (most recent call last):
  File "/var/pisi/python-2.7.2-70/work/Python-2.7.2/Lib/test/test_fileinput.py", line 40, in test_buffer_sizes
    self.buffer_size_test(t1, t2, t3, t4, bs, round)
  File "/var/pisi/python-2.7.2-70/work/Python-2.7.2/Lib/test/test_fileinput.py", line 117, in buffer_size_test
    self.assertNotEqual(m, None)
AssertionError: None == None

test test_ftplib failed -- multiple errors occurred; run in verbose mode for details

test test_getargs failed -- Traceback (most recent call last):
  File "/var/pisi/python-2.7.2-70/work/Python-2.7.2/Lib/test/test_getargs.py", line 25, in test_with_marshal
    self.assertRaises(UnicodeError, marshal.loads, arg)
  File "/var/pisi/python-2.7.2-70/work/Python-2.7.2/Lib/unittest/case.py", line 471, in assertRaises
    callableObj(*args, **kwargs)
ValueError: bad marshal data (unknown type code)

test test_htmlparser failed -- multiple errors occurred; run in verbose mode for details

test_httpservers
Traceback (most recent call last):
  File "/var/pisi/python-2.7.2-70/work/Python-2.7.2/Lib/CGIHTTPServer.py", line 251, in run_cgi
    os.execve(scriptfile, args, env)
OSError: [Errno 13] Permission denied
Traceback (most recent call last):
  File "/var/pisi/python-2.7.2-70/work/Python-2.7.2/Lib/CGIHTTPServer.py", line 251, in run_cgi
    os.execve(scriptfile, args, env)
OSError: [Errno 13] Permission denied
Traceback (most recent call last):
  File "/var/pisi/python-2.7.2-70/work/Python-2.7.2/Lib/CGIHTTPServer.py", line 251, in run_cgi
    os.execve(scriptfile, args, env)
OSError: [Errno 13] Permission denied
Traceback (most recent call last):
  File "/var/pisi/python-2.7.2-70/work/Python-2.7.2/Lib/CGIHTTPServer.py", line 251, in run_cgi
    os.execve(scriptfile, args, env)
OSError: [Errno 13] Permission denied
Traceback (most recent call last):
  File "/var/pisi/python-2.7.2-70/work/Python-2.7.2/Lib/CGIHTTPServer.py", line 251, in run_cgi
    os.execve(scriptfile, args, env)
OSError: [Errno 13] Permission denied
test test_httpservers failed -- multiple errors occurred; run in verbose mode for details

test test_lib2to3 failed -- multiple errors occurred; run in verbose mode for details

test test_os failed -- Traceback (most recent call last):
  File "/var/pisi/python-2.7.2-70/work/Python-2.7.2/Lib/test/test_os.py", line 210, in test_stat_attributes
    self.assertEqual(trunc(getattr(result, attr)),
AttributeError: 'posix.stat_result' object has no attribute 'st_atIme'

test test_poplib failed -- multiple errors occurred; run in verbose mode for details

test test_re produced unexpected output:
**********************************************************************
=== Fails on locale-sensitive match ('(?i)[abhgefdc]ij', 'HIJ', 0, 'found', 'HIJ')
=== Fails on unicode-sensitive match ('(?i)[abhgefdc]ij', 'HIJ', 0, 'found', 'HIJ')
=== Fails on locale-sensitive match ('(?i)(bc+d$|ef*g.|h?i(j|k))', 'IJ', 0, 'found+"-"+g1+"-"+g2', 'IJ-IJ-J')
=== Fails on unicode-sensitive match ('(?i)(bc+d$|ef*g.|h?i(j|k))', 'IJ', 0, 'found+"-"+g1+"-"+g2', 'IJ-IJ-J')
=== Fails on locale-sensitive match ('(?i)multiple words', 'MULTIPLE WORDS, YEAH', 0, 'found', 'MULTIPLE WORDS')
=== Fails on unicode-sensitive match ('(?i)multiple words', 'MULTIPLE WORDS, YEAH', 0, 'found', 'MULTIPLE WORDS')

**********************************************************************

test test_sgmllib failed -- multiple errors occurred; run in verbose mode for details

test_site
Warning -- sys.path was modified by test_site
test test_site failed -- Traceback (most recent call last):
  File "/var/pisi/python-2.7.2-70/work/Python-2.7.2/Lib/test/test_site.py", line 230, in test_getsitepackages
    self.assertEqual(len(dirs), 2)
AssertionError: 3 != 2

test test_smtplib failed -- multiple errors occurred; run in verbose mode for details

test test_socket failed -- Traceback (most recent call last):
  File "/var/pisi/python-2.7.2-70/work/Python-2.7.2/Lib/test/test_socket.py", line 285, in testSendtoErrors
    s.sendto(u'\u2620', sockname)
AssertionError: UnicodeEncodeError not raised

test_sqlite
/var/pisi/python-2.7.2-70/work/Python-2.7.2/Lib/sqlite3/test/dbapi.py:649: DeprecationWarning: buffer() not supported in 3.x
  b = sqlite.Binary(chr(0) + "'")
/var/pisi/python-2.7.2-70/work/Python-2.7.2/Lib/sqlite3/test/types.py:70: DeprecationWarning: buffer() not supported in 3.x
  val = buffer("Guglhupf")
/var/pisi/python-2.7.2-70/work/Python-2.7.2/Lib/sqlite3/test/types.py:234: DeprecationWarning: buffer() not supported in 3.x
  val = buffer("Guglhupf")
/var/pisi/python-2.7.2-70/work/Python-2.7.2/Lib/sqlite3/test/types.py:350: DeprecationWarning: buffer() not supported in 3.x
  result = self.con.execute('select ? as "x [bin]"', (buffer(zlib.compress(testdata)),)).fetchone()[0]
/var/pisi/python-2.7.2-70/work/Python-2.7.2/Lib/sqlite3/test/userfunctions.py:39: DeprecationWarning: buffer() not supported in 3.x
  return buffer("blob")
/var/pisi/python-2.7.2-70/work/Python-2.7.2/Lib/sqlite3/test/userfunctions.py:200: DeprecationWarning: buffer() not supported in 3.x
  self.assertEqual(val, buffer("blob"))
/var/pisi/python-2.7.2-70/work/Python-2.7.2/Lib/sqlite3/test/userfunctions.py:237: DeprecationWarning: buffer() not supported in 3.x
  cur.execute("select isblob(?)", (buffer("blob"),))
/var/pisi/python-2.7.2-70/work/Python-2.7.2/Lib/sqlite3/test/userfunctions.py:255: DeprecationWarning: buffer() not supported in 3.x
  ("foo", 5, 3.14, None, buffer("blob"),))
/var/pisi/python-2.7.2-70/work/Python-2.7.2/Lib/sqlite3/test/userfunctions.py:347: DeprecationWarning: buffer() not supported in 3.x
  cur.execute("select checkType('blob', ?)", (buffer("blob"),))
test test_sqlite failed -- Traceback (most recent call last):
  File "/var/pisi/python-2.7.2-70/work/Python-2.7.2/Lib/sqlite3/test/regression.py", line 158, in CheckSetIsolationLevel
    "isolation_level", u"\xe9")
AssertionError: UnicodeEncodeError not raised

test test_str failed -- Traceback (most recent call last):
  File "/var/pisi/python-2.7.2-70/work/Python-2.7.2/Lib/test/string_tests.py", line 864, in test_title
    self.checkequal('Format This As Title String', "fOrMaT thIs aS titLe String", 'title')
  File "/var/pisi/python-2.7.2-70/work/Python-2.7.2/Lib/test/string_tests.py", line 56, in checkequal
    realresult
AssertionError: 'Format This As Title String' != 'Format ThIs As Title String'

test test_string failed -- Traceback (most recent call last):
  File "/var/pisi/python-2.7.2-70/work/Python-2.7.2/Lib/test/test_string.py", line 105, in test_capwords
    self.assertEqual(string.capwords('ABC DEF GHI'), 'Abc Def Ghi')
AssertionError: 'Abc Def GhI' != 'Abc Def Ghi'

test test_sysconfig failed -- Traceback (most recent call last):
  File "/var/pisi/python-2.7.2-70/work/Python-2.7.2/Lib/test/test_sysconfig.py", line 133, in test_get_platform
    self.assertEqual(get_platform(), 'win-ia64')
AssertionError: 'win32' != 'win-ia64'

test test_traceback failed -- Traceback (most recent call last):
  File "/var/pisi/python-2.7.2-70/work/Python-2.7.2/Lib/test/test_traceback.py", line 169, in test_unicode
    self.assertEqual(lines, ['AssertionError: \\xe9\n'])
AssertionError: Lists differ: ['AssertionError: \xc3\xa9\n'] != ['AssertionError: \\xe9\n']

First differing element 0:
AssertionError: Ã©

AssertionError: \xe9


- ['AssertionError: \xc3\xa9\n']
?                     ^^^^^

+ ['AssertionError: \\xe9\n']
?                   +  ^

test test_ucn failed -- Traceback (most recent call last):
  File "/var/pisi/python-2.7.2-70/work/Python-2.7.2/Lib/test/test_ucn.py", line 66, in test_ascii_letters
    code = unicodedata.lookup(name)
KeyError: "undefined character name 'LATIN SMALL LETTER i'"

test test_unicode failed -- multiple errors occurred; run in verbose mode for details

test test_unicodedata failed -- multiple errors occurred; run in verbose mode for details

test test_userstring failed -- multiple errors occurred; run in verbose mode for details

-------------------------------------------------------------------------------------------
33 tests failed:
    test_argparse test_builtin test_calendar test_cfgparser
    test_codecs test_decimal test_deque test_email test_email_renamed
    test_exceptions test_fileinput test_ftplib test_getargs
    test_htmlparser test_httpservers test_lib2to3 test_optparse
    test_os test_poplib test_re test_sgmllib test_site test_smtplib
    test_socket test_sqlite test_str test_string test_sysconfig
    test_traceback test_ucn test_unicode test_unicodedata
    test_userstring

35 tests skipped:
    test_aepack test_al test_applesingle test_bsddb185 test_bsddb3
    test_cd test_cl test_codecmaps_cn test_codecmaps_hk
    test_codecmaps_jp test_codecmaps_kr test_codecmaps_tw test_curses
    test_gdb test_gl test_imgfile test_kqueue test_linuxaudiodev
    test_macos test_macostools test_msilib test_ossaudiodev
    test_scriptpackages test_smtpnet test_socketserver test_startfile
    test_sunaudiodev test_timeout test_tk test_ttk_guionly
    test_urllib2net test_urllibnet test_winreg test_winsound
    test_zipfile64
1 skip unexpected on linux2:
    test_gdb

